Workbook

Sheet 人工评分
A1: python3 scripts/run_llm_planner.py --normalize-raw runs/pilot_v0.1/raw/GPT-5.5-Thinking__canonical_v0.1__answers_public.jsonl --overwrite | B1: 难度 | C1: 领域 | D1: 任务类型 | E1: PDE/系统 | F1: 题面英文 | G1: 题面中文 | H1: 评价角度 | I1: 评价角度英文 | J1: 模型 | K1: 模型原名 | L1: 模型回答英文 | M1: 模型回答中文 | N1: 参考答案/要点 | O1: 你的评分 | P1: 错误标签 | Q1: 备注
B2: 简单 | C2: heat_transfer | D2: forward_pde_solving | E2: 1D heat equation | F2: A researcher wants to model heat diffusion along a one-dimensional rod over a fixed time interval. The thermal diffusivity is known, the initial temperature profile is provided, and both ends of the rod are held at prescribed fixed temperatures. Design a physics-informed modeling workflow to approximate the temperature field. | G2: 一位研究者希望在一个固定时间区间内，对一维杆中的热扩散过程进行建模。热扩散系数已知，初始温度分布已给出，杆的两端保持在给定的固定温度。请设计一个物理信息建模工作流，用于近似温度场。 | H2: 问题形式化 | I2: Problem Formalization | J2: DeepSeek-V4-Flash | K2: deepseek-ai/DeepSeek-V4-Flash | L2: The problem is to approximate the temperature field u(x,t) on a 1D rod of length L over time interval [0,T]. The governing PDE is the heat equation: u_t = α u_xx, where α is the known thermal diffusivity. Initial condition: u(x,0) = f(x) (provided). Boundary conditions: u(0,t) = g0(t), u(L,t) = gL(t) (prescribed fixed temperatures, i.e., Dirichlet conditions). The geometry (L) and time interval (T) are not specified; they must be provided to define the domain. | M2: 问题是在一个长度为L的1D棒上沿时间间隔[0，t]近似温度场u（x,t）。控制偏微分方程是热方程：u_t = α u_xx，其中α是已知的热扩散系数。初始条件：u(x,0) = f(x)（给定）。边界条件：u(0,t) = g0(t), u(L,t) = gL(t)（规定的固定温度，即狄利克雷条件）。几何形状(L)和时间间隔(T)未指定；必须提供它们来定义域。 | N2: 变量: x；t；u(x,t) || 已知参数: alpha = 1.0 || 未知量: u(x,t) || 区域/时间: space: x in [0,1]；time: t in [0,1] || 参数取值: alpha: 1.0 | O2: 4
A3: easy_heat_1d_dirichlet_001 | B3: 简单 | C3: heat_transfer | D3: forward_pde_solving | E3: 1D heat equation | F3: A researcher wants to model heat diffusion along a one-dimensional rod over a fixed time interval. The thermal diffusivity is known, the initial temperature profile is provided, and both ends of the rod are held at prescribed fixed temperatures. Design a physics-informed modeling workflow to approximate the temperature field. | G3: 一位研究者希望在一个固定时间区间内，对一维杆中的热扩散过程进行建模。热扩散系数已知，初始温度分布已给出，杆的两端保持在给定的固定温度。请设计一个物理信息建模工作流，用于近似温度场。 | H3: 问题形式化 | I3: Problem Formalization | J3: GPT-5.5-Thinking | K3: Open-ai/GPT-5.5-Thinking | L3: Define a one-dimensional rod domain x in [0,L] and time interval t in [0,T]. The unknown is the temperature field u(x,t), governed by u_t = alpha u_xx. The initial temperature profile u(x,0)=u0(x) is known, and both end temperatures are prescribed as Dirichlet data. The numerical values of L, T, alpha, u0(x), and the two boundary temperature functions or constants must be supplied as inputs rather than invented. | N3: 变量: x；t；u(x,t) || 已知参数: alpha = 1.0 || 未知量: u(x,t) || 区域/时间: space: x in [0,1]；time: t in [0,1] || 参数取值: alpha: 1.0 | O3: 4
A4: easy_heat_1d_dirichlet_001 | B4: 简单 | C4: heat_transfer | D4: forward_pde_solving | E4: 1D heat equation | F4: A researcher wants to model heat diffusion along a one-dimensional rod over a fixed time interval. The thermal diffusivity is known, the initial temperature profile is provided, and both ends of the rod are held at prescribed fixed temperatures. Design a physics-informed modeling workflow to approximate the temperature field. | G4: 一位研究者希望在一个固定时间区间内，对一维杆中的热扩散过程进行建模。热扩散系数已知，初始温度分布已给出，杆的两端保持在给定的固定温度。请设计一个物理信息建模工作流，用于近似温度场。 | H4: 问题形式化 | I4: Problem Formalization | J4: Kimi-K2.6 | K4: Pro/moonshotai/Kimi-K2.6 | L4: The task is to approximate the temperature field u(x,t) governed by the one-dimensional heat equation u_t = alpha * u_xx on a spatial domain (0,L) and time interval (0,T). The thermal diffusivity alpha is known, the initial profile u(x,0)=u_0(x) is provided, and both ends satisfy Dirichlet conditions u(0,t)=g_0(t) and u(L,t)=g_L(t). While the IC, BCs, and diffusivity are specified, the rod length L and final time T are implied geometry/time-horizon parameters that must be explicitly defined to construct the computational domain. The goal is a forward surrogate for u(x,t) over the full space-time cylinder. | M4: 任务是求解由一维热方程 u_t = alpha * u_xx 描述的温度场 u(x,t)，其空间域为 (0,L) ，时间区间为 (0,T) 。热扩散系数 alpha 已知，初始状态 u(x，0) = u_0(x) 已给出，两端满足狄利克雷条件 u(0,t) = g_0(t) 和 u(L,t) = g_L(t) 。虽然已指定了初始条件、边界条件和扩散系数，但杆的长度 L 和最终时间 T 作为几何/时间范围参数隐含存在，必须明确界定以构建计算域。目标是在整个时空圆柱体上获得 u(x,t) 的正向近似值。 | N4: 变量: x；t；u(x,t) || 已知参数: alpha = 1.0 || 未知量: u(x,t) || 区域/时间: space: x in [0,1]；time: t in [0,1] || 参数取值: alpha: 1.0 | O4: 5
A5: easy_heat_1d_dirichlet_001 | B5: 简单 | C5: heat_transfer | D5: forward_pde_solving | E5: 1D heat equation | F5: A researcher wants to model heat diffusion along a one-dimensional rod over a fixed time interval. The thermal diffusivity is known, the initial temperature profile is provided, and both ends of the rod are held at prescribed fixed temperatures. Design a physics-informed modeling workflow to approximate the temperature field. | G5: 一位研究者希望在一个固定时间区间内，对一维杆中的热扩散过程进行建模。热扩散系数已知，初始温度分布已给出，杆的两端保持在给定的固定温度。请设计一个物理信息建模工作流，用于近似温度场。 | H5: 问题形式化 | I5: Problem Formalization | J5: GLM-4.7 | K5: Pro/zai-org/GLM-4.7 | L5: Define the spatial domain $x \in [0, L]$ and temporal domain $t \in [0, T]$. The objective is to approximate the temperature field $u(x,t)$ governed by the heat equation $\frac{\partial u}{\partial t} = \alpha \frac{\partial^2 u}{\partial x^2}$. The initial condition is $u(x, 0) = f(x)$ and Dirichlet boundary conditions are $u(0, t) = u_{left}$ and $u(L, t) = u_{right}$. Specific values for $L, T, \alpha, f(x), u_{left}, u_{right}$ are treated as known inputs. | M5: 定义空间域为 $x \in [0, L]$，时间域为 $t \in [0， T]$。目标是近似由热方程 $\frac{\partial u}{\partial t} = \alpha \frac{\partial^2 u}{\partial x^2}$ 所描述的温度场 $u(x,t)$。初始条件为 $u(x， 0) = f(x)$，而 Dirichlet 边界条件为 $u(0, t) = u_{left}$ 和 $u(L， t) = u_{right}$。$L， T， \alpha， f(x)， u_{left}， u_{right}$ 的具体数值被视为已知输入。 | N5: 变量: x；t；u(x,t) || 已知参数: alpha = 1.0 || 未知量: u(x,t) || 区域/时间: space: x in [0,1]；time: t in [0,1] || 参数取值: alpha: 1.0 | O5: 3
A6: easy_heat_1d_dirichlet_001 | B6: 简单 | C6: heat_transfer | D6: forward_pde_solving | E6: 1D heat equation | F6: A researcher wants to model heat diffusion along a one-dimensional rod over a fixed time interval. The thermal diffusivity is known, the initial temperature profile is provided, and both ends of the rod are held at prescribed fixed temperatures. Design a physics-informed modeling workflow to approximate the temperature field. | G6: 一位研究者希望在一个固定时间区间内，对一维杆中的热扩散过程进行建模。热扩散系数已知，初始温度分布已给出，杆的两端保持在给定的固定温度。请设计一个物理信息建模工作流，用于近似温度场。 | H6: 物理约束 | I6: Physics Constraints | J6: DeepSeek-V4-Flash | K6: deepseek-ai/DeepSeek-V4-Flash | L6: The solution must satisfy the heat equation (PDE residual ≈ 0), the initial condition (IC residual ≈ 0 at t=0), and the Dirichlet boundary conditions (BC residuals ≈ 0 at x=0 and x=L). These constraints are enforced as soft penalties in the loss function. No additional constraints (e.g., flux continuity) are needed. | M6: 该解决方案必须满足热方程（偏微分方程残差 ≈ 0）、初始条件（在 t = 0 时 IC 残差 ≈ 0）以及狄利克雷边界条件（在 x = 0 和 x = L 处 BC 残差 ≈ 0）。这些约束条件作为软性惩罚项纳入损失函数中。无需其他约束条件（例如通量连续性）。 | N6: 标准PDE: u_t = alpha * u_xx, with alpha = 1.0 || 约束: initial_condition: u(x,0) is given; suggested execution-validation IC: u(x,0)=sin(pi*x)；boundary_conditions: u(0,t)=0；u(1,t)=0 || 参考条件: initial: u(x,0)=sin(pi*x)；boundary: u(0,t)=0；u(1,t)=0 | O6: 3
A7: easy_heat_1d_dirichlet_001 | B7: 简单 | C7: heat_transfer | D7: forward_pde_solving | E7: 1D heat equation | F7: A researcher wants to model heat diffusion along a one-dimensional rod over a fixed time interval. The thermal diffusivity is known, the initial temperature profile is provided, and both ends of the rod are held at prescribed fixed temperatures. Design a physics-informed modeling workflow to approximate the temperature field. | G7: 一位研究者希望在一个固定时间区间内，对一维杆中的热扩散过程进行建模。热扩散系数已知，初始温度分布已给出，杆的两端保持在给定的固定温度。请设计一个物理信息建模工作流，用于近似温度场。 | H7: 物理约束 | I7: Physics Constraints | J7: GPT-5.5-Thinking | K7: Open-ai/GPT-5.5-Thinking | L7: Enforce the heat-equation residual r(x,t)=u_t-alpha u_xx=0 in the interior. Enforce the initial condition u(x,0)=u0(x) and boundary conditions u(0,t)=g_L(t), u(L,t)=g_R(t). The workflow assumes constant diffusivity and no internal heat source; if alpha varies with temperature or position, or if a heat source exists, the PDE constraint must be changed accordingly. | N7: 标准PDE: u_t = alpha * u_xx, with alpha = 1.0 || 约束: initial_condition: u(x,0) is given; suggested execution-validation IC: u(x,0)=sin(pi*x)；boundary_conditions: u(0,t)=0；u(1,t)=0 || 参考条件: initial: u(x,0)=sin(pi*x)；boundary: u(0,t)=0；u(1,t)=0 | O7: 4
A8: easy_heat_1d_dirichlet_001 | B8: 简单 | C8: heat_transfer | D8: forward_pde_solving | E8: 1D heat equation | F8: A researcher wants to model heat diffusion along a one-dimensional rod over a fixed time interval. The thermal diffusivity is known, the initial temperature profile is provided, and both ends of the rod are held at prescribed fixed temperatures. Design a physics-informed modeling workflow to approximate the temperature field. | G8: 一位研究者希望在一个固定时间区间内，对一维杆中的热扩散过程进行建模。热扩散系数已知，初始温度分布已给出，杆的两端保持在给定的固定温度。请设计一个物理信息建模工作流，用于近似温度场。 | H8: 物理约束 | I8: Physics Constraints | J8: Kimi-K2.6 | K8: Pro/moonshotai/Kimi-K2.6 | L8: The model must satisfy: (1) PDE residual u_t - alpha*u_xx = 0 in the interior; (2) initial condition u(x,0)=u_0(x); (3) Dirichlet boundary conditions u(0,t)=g_0(t) and u(L,t)=g_L(t). A critical unstated condition is compatibility at the space-time corners: if u_0(0) != g_0(0) or u_0(L) != g_L(0), the solution loses initial temporal regularity, producing a singular layer at t=0 that complicates gradient-based training. The maximum principle and energy decay provide physical sanity checks but are not enforced automatically by the network. | M8: 该模型必须满足以下条件：（1）在内部区域，偏微分方程残差 u_t - α*u_xx = 0；（2）初始条件 u(x,0) = u_0(x)；（3）狄利克雷边界条件 u(0,t) = g_0(t) 和 u(L,t) = g_L(t)。一个关键但未明确说明的条件是空间-时间角点的兼容性：如果 u_0(0) != g_0(0) 或 u_0(L) != g_L(0)，则解会失去初始时间的光滑性，从而在 t=0 时产生一个奇异层，这会使得基于梯度的训练变得复杂。最大原理和能量衰减提供了物理合理性检查，但网络不会自动执行这些条件。 | N8: 标准PDE: u_t = alpha * u_xx, with alpha = 1.0 || 约束: initial_condition: u(x,0) is given; suggested execution-validation IC: u(x,0)=sin(pi*x)；boundary_conditions: u(0,t)=0；u(1,t)=0 || 参考条件: initial: u(x,0)=sin(pi*x)；boundary: u(0,t)=0；u(1,t)=0 | O8: 5
A9: easy_heat_1d_dirichlet_001 | B9: 简单 | C9: heat_transfer | D9: forward_pde_solving | E9: 1D heat equation | F9: A researcher wants to model heat diffusion along a one-dimensional rod over a fixed time interval. The thermal diffusivity is known, the initial temperature profile is provided, and both ends of the rod are held at prescribed fixed temperatures. Design a physics-informed modeling workflow to approximate the temperature field. | G9: 一位研究者希望在一个固定时间区间内，对一维杆中的热扩散过程进行建模。热扩散系数已知，初始温度分布已给出，杆的两端保持在给定的固定温度。请设计一个物理信息建模工作流，用于近似温度场。 | H9: 物理约束 | I9: Physics Constraints | J9: GLM-4.7 | K9: Pro/zai-org/GLM-4.7 | L9: The model must satisfy the heat equation residual $r = \frac{\partial u}{\partial t} - \alpha \frac{\partial^2 u}{\partial x^2} \approx 0$ throughout the domain. It must strictly adhere to the initial condition $u(x, 0) = f(x)$ and the boundary conditions $u(0, t) = u_{left}$, $u(L, t) = u_{right}$. | M9: 该模型在整个区域内必须满足热方程的残差条件 $r = \frac{\partial u}{\partial t} - \alpha \frac{\partial^2 u}{\partial x^2} \approx 0$ 。 | N9: 标准PDE: u_t = alpha * u_xx, with alpha = 1.0 || 约束: initial_condition: u(x,0) is given; suggested execution-validation IC: u(x,0)=sin(pi*x)；boundary_conditions: u(0,t)=0；u(1,t)=0 || 参考条件: initial: u(x,0)=sin(pi*x)；boundary: u(0,t)=0；u(1,t)=0 | O9: 2
A10: easy_heat_1d_dirichlet_001 | B10: 简单 | C10: heat_transfer | D10: forward_pde_solving | E10: 1D heat equation | F10: A researcher wants to model heat diffusion along a one-dimensional rod over a fixed time interval. The thermal diffusivity is known, the initial temperature profile is provided, and both ends of the rod are held at prescribed fixed temperatures. Design a physics-informed modeling workflow to approximate the temperature field. | G10: 一位研究者希望在一个固定时间区间内，对一维杆中的热扩散过程进行建模。热扩散系数已知，初始温度分布已给出，杆的两端保持在给定的固定温度。请设计一个物理信息建模工作流，用于近似温度场。 | H10: 模型选择 | I10: Model Choice | J10: DeepSeek-V4-Flash | K10: deepseek-ai/DeepSeek-V4-Flash | L10: A physics-informed neural network (PINN) is appropriate. The neural network takes (x,t) as inputs and outputs u(x,t). It fits the PDE type (parabolic, linear) and available data (no observations, only known IC/BC). PINNs can handle irregular domains and are robust for forward problems with known parameters. The model should have a moderate number of layers (e.g., 4-6 hidden layers, 50-100 neurons each) with tanh activation for smooth solutions. | M10: 采用基于物理原理的神经网络（PINN）是合适的。该神经网络将（x，t）作为输入，并输出 u(x,t)。它能够适应 PDE 类型（抛物型、线性）以及可用的数据（没有观测值，只有已知的初始条件/边界条件）。PINN 可以处理不规则的区域，并且对于具有已知参数的正向问题具有鲁棒性。该模型应具有适度数量的层（例如，4 - 6 个隐藏层，每个层 50 - 100 个神经元），并使用 tanh 激活函数以获得平滑的解。 | N10: 可接受模型选择: PINN；physics-informed neural network | O10: 3
A11: easy_heat_1d_dirichlet_001 | B11: 简单 | C11: heat_transfer | D11: forward_pde_solving | E11: 1D heat equation | F11: A researcher wants to model heat diffusion along a one-dimensional rod over a fixed time interval. The thermal diffusivity is known, the initial temperature profile is provided, and both ends of the rod are held at prescribed fixed temperatures. Design a physics-informed modeling workflow to approximate the temperature field. | G11: 一位研究者希望在一个固定时间区间内，对一维杆中的热扩散过程进行建模。热扩散系数已知，初始温度分布已给出，杆的两端保持在给定的固定温度。请设计一个物理信息建模工作流，用于近似温度场。 | H11: 模型选择 | I11: Model Choice | J11: GPT-5.5-Thinking | K11: Open-ai/GPT-5.5-Thinking | L11: Use a coordinate-based PINN with inputs (x,t) and scalar output u_theta(x,t). A tanh MLP is appropriate because heat-equation solutions are typically smooth after diffusion and automatic differentiation can compute u_t and u_xx. Hard imposition of Dirichlet and initial data by a trial-solution transform is preferred when the boundary functions are simple; otherwise use soft penalty losses. | N11: 可接受模型选择: PINN；physics-informed neural network | O11: 4
A12: easy_heat_1d_dirichlet_001 | B12: 简单 | C12: heat_transfer | D12: forward_pde_solving | E12: 1D heat equation | F12: A researcher wants to model heat diffusion along a one-dimensional rod over a fixed time interval. The thermal diffusivity is known, the initial temperature profile is provided, and both ends of the rod are held at prescribed fixed temperatures. Design a physics-informed modeling workflow to approximate the temperature field. | G12: 一位研究者希望在一个固定时间区间内，对一维杆中的热扩散过程进行建模。热扩散系数已知，初始温度分布已给出，杆的两端保持在给定的固定温度。请设计一个物理信息建模工作流，用于近似温度场。 | H12: 模型选择 | I12: Model Choice | J12: Kimi-K2.6 | K12: Pro/moonshotai/Kimi-K2.6 | L12: Use a fully-connected Physics-Informed Neural Network (PINN) with tanh activations and 4-6 hidden layers of 32-64 neurons. Tanh is preferred because the heat equation produces smooth solutions without shocks. Hard-enforce the Dirichlet BCs via an output transform, e.g., u_pred(x,t) = (1-x/L)*g_0(t) + (x/L)*g_L(t) + x*(L-x)*NN(x,t), so the network learns only the homogeneous correction and boundary drift is eliminated. If the initial profile contains high-frequency modes, augment the input with Fourier feature embeddings or use a modified MLP with residual connections to mitigate spectral bias. | M12: 使用具有双曲正切激活函数的全连接物理信息神经网络（PINN），并设置 4 到 6 个隐藏层，每层包含 32 到 64 个神经元。选择双曲正切函数是因为热方程能生成平滑的解，而不会出现脉冲现象。通过输出变换硬性施加狄利克雷边界条件，例如：u_pred(x,t) = (1-x/L)*g_0(t) + (x/L)*g_L(t) + x*(L-x)*NN(x,t)，这样网络就只学习均匀修正，而边界漂移则被消除。如果初始轮廓包含高频模式，则通过添加傅里叶特征嵌入或使用具有残差连接的修改后的多层感知机来减轻频谱偏差。 | N12: 可接受模型选择: PINN；physics-informed neural network | O12: 5
A13: easy_heat_1d_dirichlet_001 | B13: 简单 | C13: heat_transfer | D13: forward_pde_solving | E13: 1D heat equation | F13: A researcher wants to model heat diffusion along a one-dimensional rod over a fixed time interval. The thermal diffusivity is known, the initial temperature profile is provided, and both ends of the rod are held at prescribed fixed temperatures. Design a physics-informed modeling workflow to approximate the temperature field. | G13: 一位研究者希望在一个固定时间区间内，对一维杆中的热扩散过程进行建模。热扩散系数已知，初始温度分布已给出，杆的两端保持在给定的固定温度。请设计一个物理信息建模工作流，用于近似温度场。 | H13: 模型选择 | I13: Model Choice | J13: GLM-4.7 | K13: Pro/zai-org/GLM-4.7 | L13: A fully connected Multi-Layer Perceptron (MLP) is selected. Inputs are coordinates $(x, t)$ and output is temperature $u$. The architecture uses 4 hidden layers with 32 neurons each and Tanh activation functions. This choice provides sufficient capacity to approximate the smooth solution of the diffusion equation while remaining computationally efficient. | M13: 选择了一个全连接的多层感知机（MLP）。输入为坐标 $(x, t)$，输出为温度 $u$。该架构包含 4 个隐藏层，每个层有 32 个神经元，并采用 Tanh 激活函数。这一选择能够提供足够的拟合能力来逼近扩散方程的光滑解，同时保持计算效率。 | N13: 可接受模型选择: PINN；physics-informed neural network | O13: 3
A14: easy_heat_1d_dirichlet_001 | B14: 简单 | C14: heat_transfer | D14: forward_pde_solving | E14: 1D heat equation | F14: A researcher wants to model heat diffusion along a one-dimensional rod over a fixed time interval. The thermal diffusivity is known, the initial temperature profile is provided, and both ends of the rod are held at prescribed fixed temperatures. Design a physics-informed modeling workflow to approximate the temperature field. | G14: 一位研究者希望在一个固定时间区间内，对一维杆中的热扩散过程进行建模。热扩散系数已知，初始温度分布已给出，杆的两端保持在给定的固定温度。请设计一个物理信息建模工作流，用于近似温度场。 | H14: 训练策略 | I14: Training Strategy | J14: DeepSeek-V4-Flash | K14: deepseek-ai/DeepSeek-V4-Flash | L14: Loss = λ_PDE * MSE_PDE + λ_IC * MSE_IC + λ_BC * MSE_BC. Sample collocation points: N_f interior points (e.g., Latin hypercube or random), N_IC points at t=0 along x, N_BC points at x=0 and x=L over time. Use Adam optimizer initially, then L-BFGS for fine-tuning. Adaptive loss weighting (e.g., using gradient statistics or NTK) may improve convergence. Monitor PDE residual and IC/BC errors during training. | M14: 损失值 = λ_PDE * MSE_PDE + λ_IC * MSE_IC + λ_BC * MSE_BC。样本节点位置：N_f 个内部节点（例如，拉丁超立方体或随机分布），N_IC 个在 t=0 时沿 x 轴的位置节点，N_BC 个在 x=0 和 x=L 处随时间变化的位置节点。初始使用 Adam 优化器，然后进行 L-BFGS 优化以进行微调。自适应损失权重（例如，使用梯度统计或 NTK）可能有助于提高收敛性。在训练过程中监测 PDE 剩余值和 IC/BC 误差。 | N14: 期望loss项: PDE residual loss；initial condition loss；Dirichlet boundary loss || 期望训练策略: sample collocation points in the space-time domain；sample initial and boundary points separately；normalize inputs or nondimensionalize variables；use Adam followed by L-BFGS or an equivalent optimizer schedule | O14: 4
A15: easy_heat_1d_dirichlet_001 | B15: 简单 | C15: heat_transfer | D15: forward_pde_solving | E15: 1D heat equation | F15: A researcher wants to model heat diffusion along a one-dimensional rod over a fixed time interval. The thermal diffusivity is known, the initial temperature profile is provided, and both ends of the rod are held at prescribed fixed temperatures. Design a physics-informed modeling workflow to approximate the temperature field. | G15: 一位研究者希望在一个固定时间区间内，对一维杆中的热扩散过程进行建模。热扩散系数已知，初始温度分布已给出，杆的两端保持在给定的固定温度。请设计一个物理信息建模工作流，用于近似温度场。 | H15: 训练策略 | I15: Training Strategy | J15: GPT-5.5-Thinking | K15: Open-ai/GPT-5.5-Thinking | L15: Minimize L=lambda_f MSE(r)+lambda_ic MSE(u_theta(x,0)-u0)+lambda_bc[MSE(u_theta(0,t)-g_L)+MSE(u_theta(L,t)-g_R)]. Sample interior collocation points with Latin hypercube or Sobol sampling, add separate samples at t=0 and at x=0,L, and nondimensionalize x,t,u. Train with Adam for coarse convergence followed by L-BFGS, with adaptive loss weights if boundary or initial errors dominate. | N15: 期望loss项: PDE residual loss；initial condition loss；Dirichlet boundary loss || 期望训练策略: sample collocation points in the space-time domain；sample initial and boundary points separately；normalize inputs or nondimensionalize variables；use Adam followed by L-BFGS or an equivalent optimizer schedule | O15: 4
A16: easy_heat_1d_dirichlet_001 | B16: 简单 | C16: heat_transfer | D16: forward_pde_solving | E16: 1D heat equation | F16: A researcher wants to model heat diffusion along a one-dimensional rod over a fixed time interval. The thermal diffusivity is known, the initial temperature profile is provided, and both ends of the rod are held at prescribed fixed temperatures. Design a physics-informed modeling workflow to approximate the temperature field. | G16: 一位研究者希望在一个固定时间区间内，对一维杆中的热扩散过程进行建模。热扩散系数已知，初始温度分布已给出，杆的两端保持在给定的固定温度。请设计一个物理信息建模工作流，用于近似温度场。 | H16: 训练策略 | I16: Training Strategy | J16: Kimi-K2.6 | K16: Pro/moonshotai/Kimi-K2.6 | L16: Normalize spatial and temporal inputs to [0,1] to improve conditioning. Sample collocation points via Latin Hypercube Sampling across the interior, with additional density near t=0 and boundaries if steep transients are expected; apply residual-based adaptive refinement (RAR) to re-sample high-loss regions. Define the loss as the mean squared PDE residual plus the MSE of the initial condition (BC loss is removed by the hard transform). Optimize first with Adam (learning rate 1e-3) for 50,000-100,000 iterations, then switch to L-BFGS for high-accuracy convergence. Use adaptive weighting (e.g., NTK-based or GradNorm) to balance the PDE and IC loss terms, especially when alpha is small or the initial transient is sharp. For long time horizons, consider a sequential time-marching or causal weighting scheme to respect temporal causality. | M16: 将空间和时间输入值归一化至[0，1]范围，以改善条件性。通过拉丁超立方抽样在内部区域选取样本位置，并在 t = 0 附近以及边界处增加密度，如果预期存在陡峭的瞬态现象；应用基于残差的自适应细化（RAR）方法重新采样高损失区域。将损失定义为偏微分方程残差的均方差加上初始条件的均方误差（边界损失通过硬变换去除）。首先使用 Adam 算法（学习率为 1e-3）进行优化，优化次数为 50，000 至 100，000 次迭代，然后切换到 L-BFGS 以实现高精度收敛。使用自适应加权方法（例如基于 NTK 或 GradNorm）来平衡偏微分方程和初始条件的损失项，特别是在 alpha 较小或初始瞬态较陡峭的情况下。对于较长的时间范围，可以考虑采用顺序时间推进或因果加权方案以尊重时间因果关系。 | N16: 期望loss项: PDE residual loss；initial condition loss；Dirichlet boundary loss || 期望训练策略: sample collocation points in the space-time domain；sample initial and boundary points separately；normalize inputs or nondimensionalize variables；use Adam followed by L-BFGS or an equivalent optimizer schedule | O16: 5
A17: easy_heat_1d_dirichlet_001 | B17: 简单 | C17: heat_transfer | D17: forward_pde_solving | E17: 1D heat equation | F17: A researcher wants to model heat diffusion along a one-dimensional rod over a fixed time interval. The thermal diffusivity is known, the initial temperature profile is provided, and both ends of the rod are held at prescribed fixed temperatures. Design a physics-informed modeling workflow to approximate the temperature field. | G17: 一位研究者希望在一个固定时间区间内，对一维杆中的热扩散过程进行建模。热扩散系数已知，初始温度分布已给出，杆的两端保持在给定的固定温度。请设计一个物理信息建模工作流，用于近似温度场。 | H17: 训练策略 | I17: Training Strategy | J17: GLM-4.7 | K17: Pro/zai-org/GLM-4.7 | L17: Minimize a composite loss function $L = L_{PDE} + \lambda_{IC} L_{IC} + \lambda_{BC} L_{BC}$. Use random sampling (or Latin Hypercube) to generate collocation points for the PDE loss. Sample specifically at $t=0$ for IC and $x=0, L$ for BC. Optimize using Adam for initial convergence followed by L-BFGS for high precision. Weights $\lambda$ are tuned to balance the loss components. | M17: 最小化一个复合损失函数 $L = L_{PDE} + \lambda_{IC} L_{IC} + \lambda_{BC} L_{BC}$ 。采用随机抽样（或拉丁超立方抽样）来为 PDE 损失生成插值点。特别地，在 $t=0$ 处对 IC 进行采样，在 $x=0， L$ 处对 BC 进行采样。首先使用 Adam 进行初始收敛优化，然后使用 L-BFGS 以高精度进行优化。权重 $\lambda$ 被调整以平衡各损失项。 | N17: 期望loss项: PDE residual loss；initial condition loss；Dirichlet boundary loss || 期望训练策略: sample collocation points in the space-time domain；sample initial and boundary points separately；normalize inputs or nondimensionalize variables；use Adam followed by L-BFGS or an equivalent optimizer schedule | O17: 3
A18: easy_heat_1d_dirichlet_001 | B18: 简单 | C18: heat_transfer | D18: forward_pde_solving | E18: 1D heat equation | F18: A researcher wants to model heat diffusion along a one-dimensional rod over a fixed time interval. The thermal diffusivity is known, the initial temperature profile is provided, and both ends of the rod are held at prescribed fixed temperatures. Design a physics-informed modeling workflow to approximate the temperature field. | G18: 一位研究者希望在一个固定时间区间内，对一维杆中的热扩散过程进行建模。热扩散系数已知，初始温度分布已给出，杆的两端保持在给定的固定温度。请设计一个物理信息建模工作流，用于近似温度场。 | H18: 验证与失败风险 | I18: Validation Failure Risks | J18: DeepSeek-V4-Flash | K18: deepseek-ai/DeepSeek-V4-Flash | L18: Risk of spectral bias (low-frequency convergence) leading to inaccurate high-frequency features in the solution. Risk of unbalanced loss terms causing poor constraint satisfaction. Risk of overfitting to collocation points if too few points are used. Risk of training instability due to stiff PDE constraints. Mitigations: use adaptive sampling (e.g., resample points based on residual), learning rate scheduling, and multiple random seeds. Validate against analytical solution if available, or check energy conservation and maximum principle. | M18: 存在谱偏差（低频收敛）的风险，这可能导致解决方案中高频特征的不准确。存在不平衡损失项的风险，这会导致约束满足效果不佳。如果使用的节点数量过少，就存在过度拟合到节点点上的风险。如果偏微分方程约束过于严格，就存在训练不稳定的风险。缓解措施：采用自适应采样（例如，根据残差重新采样节点），学习率调度以及多个随机种子。如果有解析解，就用其进行验证，或者检查能量守恒和最大原理。 | N18: 期望验证: compare against analytical solution if using u(x,0)=sin(pi*x)；report PDE residual error；report initial and boundary condition errors || 常见陷阱: omits initial condition loss；omits boundary loss；hallucinates Neumann boundary conditions；treats alpha as unknown without evidence | O18: 3
A19: easy_heat_1d_dirichlet_001 | B19: 简单 | C19: heat_transfer | D19: forward_pde_solving | E19: 1D heat equation | F19: A researcher wants to model heat diffusion along a one-dimensional rod over a fixed time interval. The thermal diffusivity is known, the initial temperature profile is provided, and both ends of the rod are held at prescribed fixed temperatures. Design a physics-informed modeling workflow to approximate the temperature field. | G19: 一位研究者希望在一个固定时间区间内，对一维杆中的热扩散过程进行建模。热扩散系数已知，初始温度分布已给出，杆的两端保持在给定的固定温度。请设计一个物理信息建模工作流，用于近似温度场。 | H19: 验证与失败风险 | I19: Validation Failure Risks | J19: GPT-5.5-Thinking | K19: Open-ai/GPT-5.5-Thinking | L19: Validate against held-out analytical, numerical, or sensor values, inspect PDE residual maps, and compare time slices of u(x,t). Main risks are wrong boundary temperatures, insufficient collocation near steep initial gradients, loss imbalance, and spectral bias if u0(x) contains high-frequency structure. A wrong assumption of constant alpha or zero heat source can produce visually plausible but physically biased fields. | N19: 期望验证: compare against analytical solution if using u(x,0)=sin(pi*x)；report PDE residual error；report initial and boundary condition errors || 常见陷阱: omits initial condition loss；omits boundary loss；hallucinates Neumann boundary conditions；treats alpha as unknown without evidence | O19: 4
A20: easy_heat_1d_dirichlet_001 | B20: 简单 | C20: heat_transfer | D20: forward_pde_solving | E20: 1D heat equation | F20: A researcher wants to model heat diffusion along a one-dimensional rod over a fixed time interval. The thermal diffusivity is known, the initial temperature profile is provided, and both ends of the rod are held at prescribed fixed temperatures. Design a physics-informed modeling workflow to approximate the temperature field. | G20: 一位研究者希望在一个固定时间区间内，对一维杆中的热扩散过程进行建模。热扩散系数已知，初始温度分布已给出，杆的两端保持在给定的固定温度。请设计一个物理信息建模工作流，用于近似温度场。 | H20: 验证与失败风险 | I20: Validation Failure Risks | J20: Kimi-K2.6 | K20: Pro/moonshotai/Kimi-K2.6 | L20: Primary risks include: (i) corner incompatibility between IC and BCs causing persistent high residuals and slow convergence near (0,0) and (L,0); (ii) spectral bias preventing accurate representation of high-frequency initial data or thin boundary layers when alpha is small; (iii) causality violations or error accumulation over long time intervals if the network is trained globally without temporal ordering; (iv) insufficient collocation density leading to non-physical interpolatory modes between sample points; and (v) lack of interior observation data means validation relies entirely on PDE residual monitoring and physical consistency checks (e.g., monotonic energy decay, maximum principle), so undetected approximation errors may persist without a reference solution for verification. | M20: 主要风险包括：（i）集成电路（IC）与边界条件（BC）之间的不兼容导致在（0，0）和（L，0）附近存在持续的高残差以及缓慢收敛；（ii）当α值较小时，频谱偏差会妨碍高频率初始数据或薄边界层的准确表示；（iii）如果网络在未按时间顺序进行训练的情况下进行全局训练，则会出现因果关系违背或误差累积问题；（iv）采样点之间的插值密度不足会导致样本点之间的非物理模式；（v）由于缺乏内部观测数据，验证完全依赖于偏微分方程残差监测和物理一致性检查（例如，单调能量衰减、最大原理），因此未检测到的近似误差可能会持续存在而没有可供验证的参考解。 | N20: 期望验证: compare against analytical solution if using u(x,0)=sin(pi*x)；report PDE residual error；report initial and boundary condition errors || 常见陷阱: omits initial condition loss；omits boundary loss；hallucinates Neumann boundary conditions；treats alpha as unknown without evidence | O20: 5
A21: easy_heat_1d_dirichlet_001 | B21: 简单 | C21: heat_transfer | D21: forward_pde_solving | E21: 1D heat equation | F21: A researcher wants to model heat diffusion along a one-dimensional rod over a fixed time interval. The thermal diffusivity is known, the initial temperature profile is provided, and both ends of the rod are held at prescribed fixed temperatures. Design a physics-informed modeling workflow to approximate the temperature field. | G21: 一位研究者希望在一个固定时间区间内，对一维杆中的热扩散过程进行建模。热扩散系数已知，初始温度分布已给出，杆的两端保持在给定的固定温度。请设计一个物理信息建模工作流，用于近似温度场。 | H21: 验证与失败风险 | I21: Validation Failure Risks | J21: GLM-4.7 | K21: Pro/zai-org/GLM-4.7 | L21: Potential failure modes include spectral bias preventing the capture of sharp features in the initial profile, optimization getting trapped in local minima leading to unphysical solutions, and imbalance in loss terms causing the model to prioritize boundary conditions over the governing PDE in the interior. | M21: 潜在的故障模式包括：光谱偏差导致无法捕捉初始轮廓中的尖锐特征；优化过程陷入局部最小值，从而产生不合理的解；以及损失项的不平衡使得模型在内部优先考虑边界条件而非控制方程本身。 | N21: 期望验证: compare against analytical solution if using u(x,0)=sin(pi*x)；report PDE residual error；report initial and boundary condition errors || 常见陷阱: omits initial condition loss；omits boundary loss；hallucinates Neumann boundary conditions；treats alpha as unknown without evidence | O21: 2
A22: medium_heat_inverse_alpha_009 | B22: 中等 | C22: heat_transfer | D22: inverse_parameter_estimation | E22: 1D heat equation | F22: A laboratory measures sparse, possibly noisy temperature values at space-time locations along a one-dimensional rod. The heat equation form is known, but the thermal diffusivity is unknown. Design a physics-informed modeling workflow to infer the diffusivity and reconstruct the temperature field, including any additional physical conditions that must be specified or obtained. | G22: 一个实验室在一维杆的若干时空位置测量了稀疏且可能含噪的温度值。热方程形式已知，但热扩散系数未知。请设计一个物理信息建模工作流，用于推断扩散系数并重构温度场，同时说明还需要指定或获得哪些额外物理条件。 | H22: 问题形式化 | I22: Problem Formalization | J22: DeepSeek-V4-Flash | K22: deepseek-ai/DeepSeek-V4-Flash | L22: We aim to infer the unknown thermal diffusivity α (scalar or spatially varying) and reconstruct the temperature field u(x,t) from sparse, noisy temperature measurements at discrete (x,t) locations along a 1D rod. The heat equation ∂u/∂t = α ∂²u/∂x² is assumed. Missing conditions: initial condition u(x,0), boundary conditions at rod ends (e.g., Dirichlet, Neumann, or Robin), rod length L, measurement noise level, and whether α is constant or variable. These must be specified or estimated from data or prior knowledge. | M22: 我们的目标是根据沿一维棒上离散的（x，t）位置处的稀疏且有噪声的温度测量值，推断未知的热扩散系数α（标量或空间变化形式）并重建温度场u(x,t)。假设热方程为∂u/∂t = α ∂²u/∂x²。缺失的条件包括：初始条件u(x，0)、棒端的边界条件（例如狄利克雷、诺伊曼或罗宾边界条件）、棒的长度L、测量噪声水平以及α是否为常数或变化的。这些条件必须明确指定或从数据或先验知识中估计得出。 | N22: 变量: x；t；u(x,t)；alpha || 未知量: u(x,t)；alpha || 区域/时间: space: x in [0,1]；time: t in [0,1] || 参数取值: alpha_true: 0.5；sensor_count: 100；noise: 1 percent Gaussian noise || 评分提醒: Do not require the model to guess the private IC/BC. Full-credit plans should state that IC/BC are needed or should be incorporated if available, and should not hallucinate unsupported values.
A23: medium_heat_inverse_alpha_009 | B23: 中等 | C23: heat_transfer | D23: inverse_parameter_estimation | E23: 1D heat equation | F23: A laboratory measures sparse, possibly noisy temperature values at space-time locations along a one-dimensional rod. The heat equation form is known, but the thermal diffusivity is unknown. Design a physics-informed modeling workflow to infer the diffusivity and reconstruct the temperature field, including any additional physical conditions that must be specified or obtained. | G23: 一个实验室在一维杆的若干时空位置测量了稀疏且可能含噪的温度值。热方程形式已知，但热扩散系数未知。请设计一个物理信息建模工作流，用于推断扩散系数并重构温度场，同时说明还需要指定或获得哪些额外物理条件。 | H23: 问题形式化 | I23: Problem Formalization | J23: GPT-5.5-Thinking | K23: Open-ai/GPT-5.5-Thinking | L23: Let x in [0,L] and t in [0,T]. Infer the unknown thermal diffusivity alpha and reconstruct temperature u(x,t) from sparse observations D={(x_i,t_i,u_i^obs)} under the heat equation u_t=alpha u_xx. The workflow requires the rod length, time window, initial condition, boundary conditions, observation locations, and noise characteristics. Without these, alpha may be non-identifiable or biased by missing physics. | N23: 变量: x；t；u(x,t)；alpha || 未知量: u(x,t)；alpha || 区域/时间: space: x in [0,1]；time: t in [0,1] || 参数取值: alpha_true: 0.5；sensor_count: 100；noise: 1 percent Gaussian noise || 评分提醒: Do not require the model to guess the private IC/BC. Full-credit plans should state that IC/BC are needed or should be incorporated if available, and should not hallucinate unsupported values.
A24: medium_heat_inverse_alpha_009 | B24: 中等 | C24: heat_transfer | D24: inverse_parameter_estimation | E24: 1D heat equation | F24: A laboratory measures sparse, possibly noisy temperature values at space-time locations along a one-dimensional rod. The heat equation form is known, but the thermal diffusivity is unknown. Design a physics-informed modeling workflow to infer the diffusivity and reconstruct the temperature field, including any additional physical conditions that must be specified or obtained. | G24: 一个实验室在一维杆的若干时空位置测量了稀疏且可能含噪的温度值。热方程形式已知，但热扩散系数未知。请设计一个物理信息建模工作流，用于推断扩散系数并重构温度场，同时说明还需要指定或获得哪些额外物理条件。 | H24: 问题形式化 | I24: Problem Formalization | J24: Kimi-K2.6 | K24: Pro/moonshotai/Kimi-K2.6 | L24: The forward model is the 1D heat equation u_t = α u_xx on x ∈ [0,L], t ∈ [0,T] with unknown constant thermal diffusivity α > 0. Available information consists of sparse, noisy point measurements of temperature. Critical unspecified elements are: the domain length L, boundary conditions at both ends (Dirichlet, Neumann, or Robin), the initial condition u(x,0), and the observation noise statistics. If α is spatially varying, its regularity must also be declared. The goal is to jointly infer α and reconstruct u(x,t) everywhere. | M24: 前向模型是方程 u_t = α u_xx，其定义域为 x ∈ [0,L]，时间范围为 t ∈ [0,T]，其中未知的常数热扩散率 α > 0。可用的信息包括温度的稀疏、有噪声的点测量值。未明确的关键要素有：域长度 L、两端的边界条件（狄利克雷、诺伊曼或罗宾型）、初始条件 u(x，0) 以及观测噪声的统计信息。如果 α 是空间变化的，则还必须声明其规律性。目标是联合推断 α 并在所有位置重建 u(x,t)。 | N24: 变量: x；t；u(x,t)；alpha || 未知量: u(x,t)；alpha || 区域/时间: space: x in [0,1]；time: t in [0,1] || 参数取值: alpha_true: 0.5；sensor_count: 100；noise: 1 percent Gaussian noise || 评分提醒: Do not require the model to guess the private IC/BC. Full-credit plans should state that IC/BC are needed or should be incorporated if available, and should not hallucinate unsupported values.
A25: medium_heat_inverse_alpha_009 | B25: 中等 | C25: heat_transfer | D25: inverse_parameter_estimation | E25: 1D heat equation | F25: A laboratory measures sparse, possibly noisy temperature values at space-time locations along a one-dimensional rod. The heat equation form is known, but the thermal diffusivity is unknown. Design a physics-informed modeling workflow to infer the diffusivity and reconstruct the temperature field, including any additional physical conditions that must be specified or obtained. | G25: 一个实验室在一维杆的若干时空位置测量了稀疏且可能含噪的温度值。热方程形式已知，但热扩散系数未知。请设计一个物理信息建模工作流，用于推断扩散系数并重构温度场，同时说明还需要指定或获得哪些额外物理条件。 | H25: 问题形式化 | I25: Problem Formalization | J25: GLM-4.7 | K25: Pro/zai-org/GLM-4.7 | L25: The task is an inverse problem for the 1D heat equation $u_t = \alpha u_{xx}$ on a spatial domain $x \in [0, L]$ and time interval $t \in [0, T]$. The objective is to reconstruct the continuous temperature field $u(x,t)$ and infer the thermal diffusivity $\alpha$ (assumed constant) using sparse, noisy observations $\{(x_i, t_i, u_i)\}$. Missing Information: The Boundary Conditions (BCs) at $x=0, L$ and the Initial Condition (IC) at $t=0$ are not specified. These must be provided or assumed (e.g., Dirichlet, Neumann, or Periodic) to ensure a well-posed formulation. | M25: 该任务属于一维热方程 $u_t = \alpha u_{xx}$ 的逆问题，其空间域为 $x \in [0, L]$，时间区间为 $t \in [0, T]$。目标是通过稀疏且带有噪声的观测数据 $\{(x_i, t_i, u_i)\}$ 重建连续温度场 $u(x,t)$ 并推断热扩散系数 $\alpha$（假设为常数）。缺失信息：边界条件（BC）在 $x=0$ 和 $L$ 处以及初始条件（IC）在 $t=0$ 处未作规定。这些内容必须提供或假定（例如，狄利克雷条件、诺伊曼条件或周期条件）以确保问题的正解性。 | N25: 变量: x；t；u(x,t)；alpha || 未知量: u(x,t)；alpha || 区域/时间: space: x in [0,1]；time: t in [0,1] || 参数取值: alpha_true: 0.5；sensor_count: 100；noise: 1 percent Gaussian noise || 评分提醒: Do not require the model to guess the private IC/BC. Full-credit plans should state that IC/BC are needed or should be incorporated if available, and should not hallucinate unsupported values.
A26: medium_heat_inverse_alpha_009 | B26: 中等 | C26: heat_transfer | D26: inverse_parameter_estimation | E26: 1D heat equation | F26: A laboratory measures sparse, possibly noisy temperature values at space-time locations along a one-dimensional rod. The heat equation form is known, but the thermal diffusivity is unknown. Design a physics-informed modeling workflow to infer the diffusivity and reconstruct the temperature field, including any additional physical conditions that must be specified or obtained. | G26: 一个实验室在一维杆的若干时空位置测量了稀疏且可能含噪的温度值。热方程形式已知，但热扩散系数未知。请设计一个物理信息建模工作流，用于推断扩散系数并重构温度场，同时说明还需要指定或获得哪些额外物理条件。 | H26: 物理约束 | I26: Physics Constraints | J26: DeepSeek-V4-Flash | K26: deepseek-ai/DeepSeek-V4-Flash | L26: The solution must satisfy the heat equation exactly (or approximately via soft penalty). Boundary and initial conditions are required for well-posedness; if unknown, they must be inferred as additional parameters or functions. The diffusivity α must be positive. If α is spatially varying, additional regularization (e.g., smoothness) may be needed. The reconstruction must be consistent with the measured data within noise bounds. | M26: 待翻译：下一步可按代表题或按模型分批由我继续填入。 | N26: 标准PDE: u_t = alpha * u_xx with true alpha = 0.5 for the private reference || 约束: observations: 100 randomly sampled sparse temperature sensors with 1 percent Gaussian noise for the private reference setting；physics: heat equation form is known；initial_and_boundary_conditions: private execution reference uses u(x,0)=sin(pi*x), u(0,t)=0, u(1,t)=0; public task does not fully specify IC/BC, so a plan should request or account for them || 参考条件: initial: u(x,0)=sin(pi*x)；boundary: u(0,t)=0；u(1,t)=0；observations: 100 random space-time sensors with 1 percent Gaussian noise || 评分提醒: Do not require the model to guess the private IC/BC. Full-credit plans should state that IC/BC are needed or should be incorporated if available, and should not hallucinate unsupported values.
A27: medium_heat_inverse_alpha_009 | B27: 中等 | C27: heat_transfer | D27: inverse_parameter_estimation | E27: 1D heat equation | F27: A laboratory measures sparse, possibly noisy temperature values at space-time locations along a one-dimensional rod. The heat equation form is known, but the thermal diffusivity is unknown. Design a physics-informed modeling workflow to infer the diffusivity and reconstruct the temperature field, including any additional physical conditions that must be specified or obtained. | G27: 一个实验室在一维杆的若干时空位置测量了稀疏且可能含噪的温度值。热方程形式已知，但热扩散系数未知。请设计一个物理信息建模工作流，用于推断扩散系数并重构温度场，同时说明还需要指定或获得哪些额外物理条件。 | H27: 物理约束 | I27: Physics Constraints | J27: GPT-5.5-Thinking | K27: Open-ai/GPT-5.5-Thinking | L27: Enforce r=u_t-alpha u_xx=0 and alpha>0, for example by parameterizing alpha=softplus(beta). Enforce available initial and boundary conditions: Dirichlet, Neumann, Robin, or measured boundary temperature/flux. The standard residual assumes a homogeneous rod, constant alpha, and no internal heat source; if material properties vary or heat generation/loss exists, those terms must be included or jointly estimated. | N27: 标准PDE: u_t = alpha * u_xx with true alpha = 0.5 for the private reference || 约束: observations: 100 randomly sampled sparse temperature sensors with 1 percent Gaussian noise for the private reference setting；physics: heat equation form is known；initial_and_boundary_conditions: private execution reference uses u(x,0)=sin(pi*x), u(0,t)=0, u(1,t)=0; public task does not fully specify IC/BC, so a plan should request or account for them || 参考条件: initial: u(x,0)=sin(pi*x)；boundary: u(0,t)=0；u(1,t)=0；observations: 100 random space-time sensors with 1 percent Gaussian noise || 评分提醒: Do not require the model to guess the private IC/BC. Full-credit plans should state that IC/BC are needed or should be incorporated if available, and should not hallucinate unsupported values.
A28: medium_heat_inverse_alpha_009 | B28: 中等 | C28: heat_transfer | D28: inverse_parameter_estimation | E28: 1D heat equation | F28: A laboratory measures sparse, possibly noisy temperature values at space-time locations along a one-dimensional rod. The heat equation form is known, but the thermal diffusivity is unknown. Design a physics-informed modeling workflow to infer the diffusivity and reconstruct the temperature field, including any additional physical conditions that must be specified or obtained. | G28: 一个实验室在一维杆的若干时空位置测量了稀疏且可能含噪的温度值。热方程形式已知，但热扩散系数未知。请设计一个物理信息建模工作流，用于推断扩散系数并重构温度场，同时说明还需要指定或获得哪些额外物理条件。 | H28: 物理约束 | I28: Physics Constraints | J28: Kimi-K2.6 | K28: Pro/moonshotai/Kimi-K2.6 | L28: Governing PDE residual u_t - α u_xx = 0 must vanish in the interior. Positivity of α is required, enforced by parameterizing α = exp(β). The problem is ill-posed without boundary and initial conditions; these must be supplied or independently measured. The heat equation parabolic nature enforces strong spatial smoothing for t > 0, which regularizes the solution. Transient data are necessary for identifiability; steady-state or purely spatial data cannot determine α. Observation noise should be treated as aleatoric uncertainty rather than interpolated exactly. | M28: 待翻译：下一步可按代表题或按模型分批由我继续填入。 | N28: 标准PDE: u_t = alpha * u_xx with true alpha = 0.5 for the private reference || 约束: observations: 100 randomly sampled sparse temperature sensors with 1 percent Gaussian noise for the private reference setting；physics: heat equation form is known；initial_and_boundary_conditions: private execution reference uses u(x,0)=sin(pi*x), u(0,t)=0, u(1,t)=0; public task does not fully specify IC/BC, so a plan should request or account for them || 参考条件: initial: u(x,0)=sin(pi*x)；boundary: u(0,t)=0；u(1,t)=0；observations: 100 random space-time sensors with 1 percent Gaussian noise || 评分提醒: Do not require the model to guess the private IC/BC. Full-credit plans should state that IC/BC are needed or should be incorporated if available, and should not hallucinate unsupported values.
A29: medium_heat_inverse_alpha_009 | B29: 中等 | C29: heat_transfer | D29: inverse_parameter_estimation | E29: 1D heat equation | F29: A laboratory measures sparse, possibly noisy temperature values at space-time locations along a one-dimensional rod. The heat equation form is known, but the thermal diffusivity is unknown. Design a physics-informed modeling workflow to infer the diffusivity and reconstruct the temperature field, including any additional physical conditions that must be specified or obtained. | G29: 一个实验室在一维杆的若干时空位置测量了稀疏且可能含噪的温度值。热方程形式已知，但热扩散系数未知。请设计一个物理信息建模工作流，用于推断扩散系数并重构温度场，同时说明还需要指定或获得哪些额外物理条件。 | H29: 物理约束 | I29: Physics Constraints | J29: GLM-4.7 | K29: Pro/zai-org/GLM-4.7 | L29: 1. PDE Residual: The model must satisfy $f(x,t) = u_t - \alpha u_{xx} = 0$ at all collocation points. 2. Positivity: The diffusivity parameter must satisfy $\alpha > 0$. 3. Boundary/Initial Consistency: The solution must adhere to the (required) BCs and ICs. 4. Smoothness: The temperature field $u(x,t)$ is expected to be smooth in space and time for standard heat diffusion. | M29: 待翻译：下一步可按代表题或按模型分批由我继续填入。 | N29: 标准PDE: u_t = alpha * u_xx with true alpha = 0.5 for the private reference || 约束: observations: 100 randomly sampled sparse temperature sensors with 1 percent Gaussian noise for the private reference setting；physics: heat equation form is known；initial_and_boundary_conditions: private execution reference uses u(x,0)=sin(pi*x), u(0,t)=0, u(1,t)=0; public task does not fully specify IC/BC, so a plan should request or account for them || 参考条件: initial: u(x,0)=sin(pi*x)；boundary: u(0,t)=0；u(1,t)=0；observations: 100 random space-time sensors with 1 percent Gaussian noise || 评分提醒: Do not require the model to guess the private IC/BC. Full-credit plans should state that IC/BC are needed or should be incorporated if available, and should not hallucinate unsupported values.
A30: medium_heat_inverse_alpha_009 | B30: 中等 | C30: heat_transfer | D30: inverse_parameter_estimation | E30: 1D heat equation | F30: A laboratory measures sparse, possibly noisy temperature values at space-time locations along a one-dimensional rod. The heat equation form is known, but the thermal diffusivity is unknown. Design a physics-informed modeling workflow to infer the diffusivity and reconstruct the temperature field, including any additional physical conditions that must be specified or obtained. | G30: 一个实验室在一维杆的若干时空位置测量了稀疏且可能含噪的温度值。热方程形式已知，但热扩散系数未知。请设计一个物理信息建模工作流，用于推断扩散系数并重构温度场，同时说明还需要指定或获得哪些额外物理条件。 | H30: 模型选择 | I30: Model Choice | J30: DeepSeek-V4-Flash | K30: deepseek-ai/DeepSeek-V4-Flash | L30: A physics-informed neural network (PINN) is appropriate: it can handle sparse data, incorporate the PDE as a loss term, and infer α as a trainable parameter (or as a neural network output if spatially varying). The network outputs u(x,t) and optionally α(x). The PDE residual loss enforces physics, while data loss fits measurements. This choice handles the inverse problem and noisy data without requiring a grid or explicit numerical solver. | M30: 待翻译：下一步可按代表题或按模型分批由我继续填入。 | N30: 可接受模型选择: PINN with trainable alpha；physics-informed neural network with parameter inference || 评分提醒: Do not require the model to guess the private IC/BC. Full-credit plans should state that IC/BC are needed or should be incorporated if available, and should not hallucinate unsupported values.
A31: medium_heat_inverse_alpha_009 | B31: 中等 | C31: heat_transfer | D31: inverse_parameter_estimation | E31: 1D heat equation | F31: A laboratory measures sparse, possibly noisy temperature values at space-time locations along a one-dimensional rod. The heat equation form is known, but the thermal diffusivity is unknown. Design a physics-informed modeling workflow to infer the diffusivity and reconstruct the temperature field, including any additional physical conditions that must be specified or obtained. | G31: 一个实验室在一维杆的若干时空位置测量了稀疏且可能含噪的温度值。热方程形式已知，但热扩散系数未知。请设计一个物理信息建模工作流，用于推断扩散系数并重构温度场，同时说明还需要指定或获得哪些额外物理条件。 | H31: 模型选择 | I31: Model Choice | J31: GPT-5.5-Thinking | K31: Open-ai/GPT-5.5-Thinking | L31: Use an inverse PINN with network output u_theta(x,t) and trainable scalar alpha. This fits the inverse parameter-estimation task because sparse data provide field anchors while the PDE residual constrains physically admissible temperature evolution. For noisy data, use a robust or probabilistic PINN so alpha uncertainty is reported rather than a single overconfident estimate. | N31: 可接受模型选择: PINN with trainable alpha；physics-informed neural network with parameter inference || 评分提醒: Do not require the model to guess the private IC/BC. Full-credit plans should state that IC/BC are needed or should be incorporated if available, and should not hallucinate unsupported values.
A32: medium_heat_inverse_alpha_009 | B32: 中等 | C32: heat_transfer | D32: inverse_parameter_estimation | E32: 1D heat equation | F32: A laboratory measures sparse, possibly noisy temperature values at space-time locations along a one-dimensional rod. The heat equation form is known, but the thermal diffusivity is unknown. Design a physics-informed modeling workflow to infer the diffusivity and reconstruct the temperature field, including any additional physical conditions that must be specified or obtained. | G32: 一个实验室在一维杆的若干时空位置测量了稀疏且可能含噪的温度值。热方程形式已知，但热扩散系数未知。请设计一个物理信息建模工作流，用于推断扩散系数并重构温度场，同时说明还需要指定或获得哪些额外物理条件。 | H32: 模型选择 | I32: Model Choice | J32: Kimi-K2.6 | K32: Pro/moonshotai/Kimi-K2.6 | L32: A Physics-Informed Neural Network (PINN) is selected: a fully-connected network mapping (x,t) → u with 6–8 layers, 32–64 neurons per layer, and tanh activation. The unknown α is a trainable scalar appended to the network parameters. This choice is justified because PINNs are mesh-free, handle sparse scattered data natively, and embed the PDE and parameter estimation into a single differentiable loss landscape. If initial transients contain high frequencies, Fourier feature embeddings or sinusoidal activations can be substituted. | M32: 待翻译：下一步可按代表题或按模型分批由我继续填入。 | N32: 可接受模型选择: PINN with trainable alpha；physics-informed neural network with parameter inference || 评分提醒: Do not require the model to guess the private IC/BC. Full-credit plans should state that IC/BC are needed or should be incorporated if available, and should not hallucinate unsupported values.
A33: medium_heat_inverse_alpha_009 | B33: 中等 | C33: heat_transfer | D33: inverse_parameter_estimation | E33: 1D heat equation | F33: A laboratory measures sparse, possibly noisy temperature values at space-time locations along a one-dimensional rod. The heat equation form is known, but the thermal diffusivity is unknown. Design a physics-informed modeling workflow to infer the diffusivity and reconstruct the temperature field, including any additional physical conditions that must be specified or obtained. | G33: 一个实验室在一维杆的若干时空位置测量了稀疏且可能含噪的温度值。热方程形式已知，但热扩散系数未知。请设计一个物理信息建模工作流，用于推断扩散系数并重构温度场，同时说明还需要指定或获得哪些额外物理条件。 | H33: 模型选择 | I33: Model Choice | J33: GLM-4.7 | K33: Pro/zai-org/GLM-4.7 | L33: A Physics-Informed Neural Network (PINN) is selected. The architecture is a fully connected Multi-Layer Perceptron (MLP) with inputs $(x, t)$ and output $u$. The thermal diffusivity $\alpha$ is treated as a trainable scalar variable. Justification: PINNs are effective for inverse problems as they embed the PDE directly into the loss function, allowing the model to learn from sparse data while respecting the underlying physics, and they handle the continuous nature of the solution without requiring a mesh. | M33: 待翻译：下一步可按代表题或按模型分批由我继续填入。 | N33: 可接受模型选择: PINN with trainable alpha；physics-informed neural network with parameter inference || 评分提醒: Do not require the model to guess the private IC/BC. Full-credit plans should state that IC/BC are needed or should be incorporated if available, and should not hallucinate unsupported values.
A34: medium_heat_inverse_alpha_009 | B34: 中等 | C34: heat_transfer | D34: inverse_parameter_estimation | E34: 1D heat equation | F34: A laboratory measures sparse, possibly noisy temperature values at space-time locations along a one-dimensional rod. The heat equation form is known, but the thermal diffusivity is unknown. Design a physics-informed modeling workflow to infer the diffusivity and reconstruct the temperature field, including any additional physical conditions that must be specified or obtained. | G34: 一个实验室在一维杆的若干时空位置测量了稀疏且可能含噪的温度值。热方程形式已知，但热扩散系数未知。请设计一个物理信息建模工作流，用于推断扩散系数并重构温度场，同时说明还需要指定或获得哪些额外物理条件。 | H34: 训练策略 | I34: Training Strategy | J34: DeepSeek-V4-Flash | K34: deepseek-ai/DeepSeek-V4-Flash | L34: Use a fully connected neural network with inputs (x,t) and output u. If α is constant, treat it as a trainable scalar; if spatially varying, output α from a separate network or as an additional output. Loss = λ_data * MSE(data, prediction) + λ_pde * MSE(PDE residual) + λ_ic * MSE(initial condition) + λ_bc * MSE(boundary conditions) + λ_reg * regularization (e.g., L2 on α gradients). Sample collocation points for PDE residual via Latin hypercube or random sampling. Use Adam optimizer initially, then L-BFGS for fine-tuning. Noise handling: use a robust loss (e.g., Huber) or weight data points by inverse noise variance. Validate on held-out data. | M34: 待翻译：下一步可按代表题或按模型分批由我继续填入。 | N34: 期望loss项: PDE residual loss with trainable alpha；data loss on sparse noisy sensor measurements；initial condition loss if IC is available；boundary condition loss if BC is available；positivity constraint or positive parameterization for alpha || 期望训练策略: jointly optimize network weights and alpha；enforce alpha positivity through parameterization or constraints；balance data and physics losses under noisy sparse observations；use held-out sensors for validation；explicitly state that IC/BC information is required if not given || 评分提醒: Do not require the model to guess the private IC/BC. Full-credit plans should state that IC/BC are needed or should be incorporated if available, and should not hallucinate unsupported values.
A35: medium_heat_inverse_alpha_009 | B35: 中等 | C35: heat_transfer | D35: inverse_parameter_estimation | E35: 1D heat equation | F35: A laboratory measures sparse, possibly noisy temperature values at space-time locations along a one-dimensional rod. The heat equation form is known, but the thermal diffusivity is unknown. Design a physics-informed modeling workflow to infer the diffusivity and reconstruct the temperature field, including any additional physical conditions that must be specified or obtained. | G35: 一个实验室在一维杆的若干时空位置测量了稀疏且可能含噪的温度值。热方程形式已知，但热扩散系数未知。请设计一个物理信息建模工作流，用于推断扩散系数并重构温度场，同时说明还需要指定或获得哪些额外物理条件。 | H35: 训练策略 | I35: Training Strategy | J35: GPT-5.5-Thinking | K35: Open-ai/GPT-5.5-Thinking | L35: Minimize L=lambda_d data_loss+lambda_f MSE(u_t-alpha u_xx)+lambda_ic L_ic+lambda_bc L_bc. Use Huber or variance-weighted data loss for noisy sensors. Sample collocation points throughout the domain and concentrate additional points near sensors, boundaries, and large thermal gradients. Nondimensionalize variables, train beta and network weights with Adam then L-BFGS, and estimate uncertainty using ensembles, bootstrap resampling, or Bayesian treatment. | N35: 期望loss项: PDE residual loss with trainable alpha；data loss on sparse noisy sensor measurements；initial condition loss if IC is available；boundary condition loss if BC is available；positivity constraint or positive parameterization for alpha || 期望训练策略: jointly optimize network weights and alpha；enforce alpha positivity through parameterization or constraints；balance data and physics losses under noisy sparse observations；use held-out sensors for validation；explicitly state that IC/BC information is required if not given || 评分提醒: Do not require the model to guess the private IC/BC. Full-credit plans should state that IC/BC are needed or should be incorporated if available, and should not hallucinate unsupported values.
A36: medium_heat_inverse_alpha_009 | B36: 中等 | C36: heat_transfer | D36: inverse_parameter_estimation | E36: 1D heat equation | F36: A laboratory measures sparse, possibly noisy temperature values at space-time locations along a one-dimensional rod. The heat equation form is known, but the thermal diffusivity is unknown. Design a physics-informed modeling workflow to infer the diffusivity and reconstruct the temperature field, including any additional physical conditions that must be specified or obtained. | G36: 一个实验室在一维杆的若干时空位置测量了稀疏且可能含噪的温度值。热方程形式已知，但热扩散系数未知。请设计一个物理信息建模工作流，用于推断扩散系数并重构温度场，同时说明还需要指定或获得哪些额外物理条件。 | H36: 训练策略 | I36: Training Strategy | J36: Kimi-K2.6 | K36: Pro/moonshotai/Kimi-K2.6 | L36: Define the composite loss L = λ_d L_data + λ_p L_pde + λ_b L_bcic. L_data is MSE on sparse observations (use Huber loss if outliers are suspected). L_pde is the squared residual on collocation points sampled via Latin Hypercube Sampling; apply residual-based adaptive refinement to add points where |R| is large. L_bcic penalizes deviations from any known boundary or initial data—if these are unknown, the workflow must halt until they are obtained. Optimize first with Adam (lr ~ 1e-3) for 20k–50k steps, then fine-tune with L-BFGS. Use adaptive weighting (e.g., GradNorm) to balance terms. Validate on a held-out subset of observations (10–20%) and monitor the PDE residual norm and the physical plausibility of α. | M36: 待翻译：下一步可按代表题或按模型分批由我继续填入。 | N36: 期望loss项: PDE residual loss with trainable alpha；data loss on sparse noisy sensor measurements；initial condition loss if IC is available；boundary condition loss if BC is available；positivity constraint or positive parameterization for alpha || 期望训练策略: jointly optimize network weights and alpha；enforce alpha positivity through parameterization or constraints；balance data and physics losses under noisy sparse observations；use held-out sensors for validation；explicitly state that IC/BC information is required if not given || 评分提醒: Do not require the model to guess the private IC/BC. Full-credit plans should state that IC/BC are needed or should be incorporated if available, and should not hallucinate unsupported values.
A37: medium_heat_inverse_alpha_009 | B37: 中等 | C37: heat_transfer | D37: inverse_parameter_estimation | E37: 1D heat equation | F37: A laboratory measures sparse, possibly noisy temperature values at space-time locations along a one-dimensional rod. The heat equation form is known, but the thermal diffusivity is unknown. Design a physics-informed modeling workflow to infer the diffusivity and reconstruct the temperature field, including any additional physical conditions that must be specified or obtained. | G37: 一个实验室在一维杆的若干时空位置测量了稀疏且可能含噪的温度值。热方程形式已知，但热扩散系数未知。请设计一个物理信息建模工作流，用于推断扩散系数并重构温度场，同时说明还需要指定或获得哪些额外物理条件。 | H37: 训练策略 | I37: Training Strategy | J37: GLM-4.7 | K37: Pro/zai-org/GLM-4.7 | L37: Loss Function: $\mathcal{L} = \lambda_{data} \mathcal{L}_{data} + \lambda_{PDE} \mathcal{L}_{PDE} + \lambda_{BC} \mathcal{L}_{BC} + \lambda_{IC} \mathcal{L}_{IC}$. $\mathcal{L}_{data}$ is the MSE on the sparse observations. $\mathcal{L}_{PDE}$ is the MSE of the residual evaluated on random collocation points. $\mathcal{L}_{BC}$ and $\mathcal{L}_{IC}$ enforce the (user-specified) boundary and initial conditions. Optimization: Use Adam for initial convergence followed by L-BFGS for high precision. Sampling: Use Latin Hypercube Sampling (LHS) for collocation points to ensure domain coverage. | M37: 待翻译：下一步可按代表题或按模型分批由我继续填入。 | N37: 期望loss项: PDE residual loss with trainable alpha；data loss on sparse noisy sensor measurements；initial condition loss if IC is available；boundary condition loss if BC is available；positivity constraint or positive parameterization for alpha || 期望训练策略: jointly optimize network weights and alpha；enforce alpha positivity through parameterization or constraints；balance data and physics losses under noisy sparse observations；use held-out sensors for validation；explicitly state that IC/BC information is required if not given || 评分提醒: Do not require the model to guess the private IC/BC. Full-credit plans should state that IC/BC are needed or should be incorporated if available, and should not hallucinate unsupported values.
